Workbook
Name N_G8_TULIPS_SCORE: _xlfn._xlws.FILTER(#REF!,#REF!,#REF!=N_G8_TULIPS)
Name N_G8_TULIPS_SCORE: _xlfn._xlws.FILTER(#REF!,#REF!,#REF!=N_G8_TULIPS)

Sheet Score_Sheet
A1: Username | B1: First Name | C1: Last Name | D1: Email | E1: Phone | F1: No. Of Correct Answers | G1: No. Of incorrect Answers | H1: No. Of unanswered Questions | I1: Time Taken | J1: Raw Score | K1: Percentage | L1: Batch | M1: Start Date | N1: End Date | O1: Location | P1: Access Code | Q1: Exam Mode | R1: Physics Score | S1: No. Of incorrect Answers in Physics | T1: No. Of correct Answers in Physics | U1: Chemistry Score | V1: No. Of incorrect Answers in Chemistry | W1: No. Of correct Answers in Chemistry | X1: Mathematics Score | Y1: No. Of incorrect Answers in Mathematics | Z1: No. Of correct Answers in Mathematics | AA1: Physics Score | AB1: No. Of incorrect Answers in Physics | AC1: No. Of correct Answers in Physics | AD1: Chemistry Score | AE1: No. Of incorrect Answers in Chemistry | AF1: No. Of correct Answers in Chemistry | AG1: Mathematics Score | AH1: No. Of incorrect Answers in Mathematics | AI1: No. Of correct Answers in Mathematics
A2: 22NGS0286 | B2: DOODALA TESHMITA | F2: 60 | G2: 0 | H2: 0 | I2: 0.046851852 | J2: 240 | K2: 100 | L2: P_G6_TULIPS | M2: 46095.431 | N2: 46095.478 | O2: Online | Q2: Online | R2: 80 | S2: 0 | T2: 20 | U2: 80 | V2: 0 | W2: 20 | X2: 80 | Y2: 0 | Z2: 20 | AA2: 80 | AB2: 0 | AC2: 20 | AD2: 80 | AE2: 0 | AF2: 20 | AG2: 80 | AH2: 0 | AI2: 20
A3: 22NGS0044 | B3: Keerthan KUDURUPAKA | F3: 60 | G3: 0 | H3: 0 | I3: 0.048599537 | J3: 240 | K3: 100 | L3: P_G6_TULIPS | M3: 46095.441 | N3: 46095.49 | O3: Online | Q3: Online | R3: 80 | S3: 0 | T3: 20 | U3: 80 | V3: 0 | W3: 20 | X3: 80 | Y3: 0 | Z3: 20 | AA3: 80 | AB3: 0 | AC3: 20 | AD3: 80 | AE3: 0 | AF3: 20 | AG3: 80 | AH3: 0 | AI3: 20
A4: 25NGS0041 | B4: LELLA VYSHNAVI | F4: 59 | G4: 1 | H4: 0 | I4: 0.045300926 | J4: 236 | K4: 98.33 | L4: P_G6_TULIPS | M4: 46095.432 | N4: 46095.478 | O4: Online | Q4: Online | R4: 80 | S4: 0 | T4: 20 | U4: 76 | V4: 1 | W4: 19 | X4: 80 | Y4: 0 | Z4: 20 | AA4: 80 | AB4: 0 | AC4: 20 | AD4: 76 | AE4: 1 | AF4: 19 | AG4: 80 | AH4: 0 | AI4: 20
A5: 22NGS0041 | B5: Charanveer | F5: 57 | G5: 3 | H5: 0 | I5: 0.044907407 | J5: 228 | K5: 95 | L5: P_G6_DAFFFODILS | M5: 46095.438 | N5: 46095.483 | O5: Online | Q5: Online | R5: 76 | S5: 1 | T5: 19 | U5: 72 | V5: 2 | W5: 18 | X5: 80 | Y5: 0 | Z5: 20 | AA5: 76 | AB5: 1 | AC5: 19 | AD5: 72 | AE5: 2 | AF5: 18 | AG5: 80 | AH5: 0 | AI5: 20
A6: 22NGS0177 | B6: TULASIRAM RAVILLA | F6: 56 | G6: 3 | H6: 1 | I6: 0.022881944 | J6: 224 | K6: 93.33 | L6: P_G6_IRIS | M6: 46095.432 | N6: 46095.455 | O6: Online | Q6: Online | R6: 80 | S6: 0 | T6: 20 | U6: 68 | V6: 3 | W6: 17 | X6: 76 | Y6: 0 | Z6: 19 | AA6: 80 | AB6: 0 | AC6: 20 | AD6: 68 | AE6: 3 | AF6: 17 | AG6: 76 | AH6: 0 | AI6: 19
A7: 23NGS0094 | B7: SAMARTH PRASAD | F7: 56 | G7: 4 | H7: 0 | I7: 0.029791667 | J7: 224 | K7: 93.33 | L7: P_G6_IRIS | M7: 46095.447 | N7: 46095.476 | O7: Online | Q7: Online | R7: 80 | S7: 0 | T7: 20 | U7: 72 | V7: 2 | W7: 18 | X7: 72 | Y7: 2 | Z7: 18 | AA7: 80 | AB7: 0 | AC7: 20 | AD7: 72 | AE7: 2 | AF7: 18 | AG7: 72 | AH7: 2 | AI7: 18
A8: 23NGS0265 | B8: S. NAGA SRI SAI KUTHRIK | F8: 56 | G8: 4 | H8: 0 | I8: 0.04150463 | J8: 224 | K8: 93.33 | L8: P_G6_DAFFFODILS | M8: 46095.432 | N8: 46095.474 | O8: Online | Q8: Online | R8: 72 | S8: 2 | T8: 18 | U8: 80 | V8: 0 | W8: 20 | X8: 72 | Y8: 2 | Z8: 18 | AA8: 72 | AB8: 2 | AC8: 18 | AD8: 80 | AE8: 0 | AF8: 20 | AG8: 72 | AH8: 2 | AI8: 18
A9: 22NGS0051 | B9: Shanvitha I | F9: 55 | G9: 5 | H9: 0 | I9: 0.038125 | J9: 220 | K9: 91.67 | L9: P_G6_TULIPS | M9: 46095.432 | N9: 46095.471 | O9: Online | Q9: Online | R9: 80 | S9: 0 | T9: 20 | U9: 80 | V9: 0 | W9: 20 | X9: 60 | Y9: 5 | Z9: 15 | AA9: 80 | AB9: 0 | AC9: 20 | AD9: 80 | AE9: 0 | AF9: 20 | AG9: 60 | AH9: 5 | AI9: 15
A10: 22NGS0185 | B10: REYANSH NUSETTI | F10: 55 | G10: 5 | H10: 0 | I10: 0.056064815 | J10: 220 | K10: 91.67 | L10: P_G6_TULIPS | M10: 46095.445 | N10: 46095.502 | O10: Online | Q10: Online | R10: 76 | S10: 1 | T10: 19 | U10: 72 | V10: 2 | W10: 18 | X10: 72 | Y10: 2 | Z10: 18 | AA10: 76 | AB10: 1 | AC10: 19 | AD10: 72 | AE10: 2 | AF10: 18 | AG10: 72 | AH10: 2 | AI10: 18
A11: 23NGS0027 | B11: MANDA ARJUN KARTHIKEYA | F11: 55 | G11: 5 | H11: 0 | I11: 0.045335648 | J11: 220 | K11: 91.67 | L11: P_G6_DAFFFODILS | M11: 46095.431 | N11: 46095.477 | O11: Online | Q11: Online | R11: 76 | S11: 1 | T11: 19 | U11: 64 | V11: 4 | W11: 16 | X11: 80 | Y11: 0 | Z11: 20 | AA11: 76 | AB11: 1 | AC11: 19 | AD11: 64 | AE11: 4 | AF11: 16 | AG11: 80 | AH11: 0 | AI11: 20
A12: 25NGS0083 | B12: SAMMANU VARSHITHA | F12: 52 | G12: 8 | H12: 0 | I12: 0.029837963 | J12: 208 | K12: 86.67 | L12: P_G6_TULIPS | M12: 46095.447 | N12: 46095.477 | O12: Online | Q12: Online | R12: 80 | S12: 0 | T12: 20 | U12: 48 | V12: 8 | W12: 12 | X12: 80 | Y12: 0 | Z12: 20 | AA12: 80 | AB12: 0 | AC12: 20 | AD12: 48 | AE12: 8 | AF12: 12 | AG12: 80 | AH12: 0 | AI12: 20
A13: 24NGS0266 | B13: D. DHAARMIK | F13: 49 | G13: 10 | H13: 1 | I13: 0.033634259 | J13: 196 | K13: 81.67 | L13: P_G6_TULIPS | M13: 46095.444 | N13: 46095.478 | O13: Online | Q13: Online | R13: 72 | S13: 2 | T13: 18 | U13: 72 | V13: 2 | W13: 18 | X13: 52 | Y13: 6 | Z13: 13 | AA13: 72 | AB13: 2 | AC13: 18 | AD13: 72 | AE13: 2 | AF13: 18 | AG13: 52 | AH13: 6 | AI13: 13
... A55: 24NGS0063 | B55: DUGGARASI HARSHIKA | F55: 0 | G55: 0 | H55: 60 | I55: 0.00015046296 | J55: 0 | K55: 0 | L55: P_G6_DAFFFODILS | M55: 46095.451 | N55: 46095.451 | O55: Online | Q55: Online | R55: 0 | S55: 0 | T55: 0 | U55: 0 | V55: 0 | W55: 0 | X55: 0 | Y55: 0 | Z55: 0 | AA55: 0 | AB55: 0 | AC55: 0 | AD55: 0 | AE55: 0 | AF55: 0 | AG55: 0 | AH55: 0 | AI55: 0
A56: 25NGSN6001 | B56: AAHIL MOHAMMED | F56: AB | G56: AB | H56: AB | I56: AB | J56: AB | K56: AB | L56: N_G6_TULIPS | M56: AB | N56: AB | O56: AB | P56: AB | Q56: AB | R56: AB | S56: AB | T56: AB | U56: AB | V56: AB | W56: AB | X56: AB | Y56: AB | Z56: AB | AA56: AB | AB56: AB | AC56: AB | AD56: AB | AE56: AB | AF56: AB | AG56: AB | AH56: AB | AI56: AB
A57: 25NGSN6003 | B57: BHARGAVI DUBBA | F57: AB | G57: AB | H57: AB | I57: AB | J57: AB | K57: AB | L57: N_G6_TULIPS | M57: AB | N57: AB | O57: AB | P57: AB | Q57: AB | R57: AB | S57: AB | T57: AB | U57: AB | V57: AB | W57: AB | X57: AB | Y57: AB | Z57: AB | AA57: AB | AB57: AB | AC57: AB | AD57: AB | AE57: AB | AF57: AB | AG57: AB | AH57: AB | AI57: AB
A58: 25NGSN608 | B58: P NIRVIGNA | F58: AB | G58: AB | H58: AB | I58: AB | J58: AB | K58: AB | L58: N_G6_TULIPS | M58: AB | N58: AB | O58: AB | P58: AB | Q58: AB | R58: AB | S58: AB | T58: AB | U58: AB | V58: AB | W58: AB | X58: AB | Y58: AB | Z58: AB | AA58: AB | AB58: AB | AC58: AB | AD58: AB | AE58: AB | AF58: AB | AG58: AB | AH58: AB | AI58: AB
A59: 25NGSN617 | B59: A. Vedick | F59: AB | G59: AB | H59: AB | I59: AB | J59: AB | K59: AB | L59: N_G6_TULIPS | M59: AB | N59: AB | O59: AB | P59: AB | Q59: AB | R59: AB | S59: AB | T59: AB | U59: AB | V59: AB | W59: AB | X59: AB | Y59: AB | Z59: AB | AA59: AB | AB59: AB | AC59: AB | AD59: AB | AE59: AB | AF59: AB | AG59: AB | AH59: AB | AI59: AB
A60: 22NGS0458 | B60: A AKSHAY | F60: AB | G60: AB | H60: AB | I60: AB | J60: AB | K60: AB | L60: P_G6_DAFFFODILS | M60: AB | N60: AB | O60: AB | P60: AB | Q60: AB | R60: AB | S60: AB | T60: AB | U60: AB | V60: AB | W60: AB | X60: AB | Y60: AB | Z60: AB | AA60: AB | AB60: AB | AC60: AB | AD60: AB | AE60: AB | AF60: AB | AG60: AB | AH60: AB | AI60: AB
A61: 24NGS0060 | B61: BARRI SARANYASRI | F61: AB | G61: AB | H61: AB | I61: AB | J61: AB | K61: AB | L61: P_G6_DAFFFODILS | M61: AB | N61: AB | O61: AB | P61: AB | Q61: AB | R61: AB | S61: AB | T61: AB | U61: AB | V61: AB | W61: AB | X61: AB | Y61: AB | Z61: AB | AA61: AB | AB61: AB | AC61: AB | AD61: AB | AE61: AB | AF61: AB | AG61: AB | AH61: AB | AI61: AB
A62: 22NGS0182 | B62: D SAANVIKA | F62: AB | G62: AB | H62: AB | I62: AB | J62: AB | K62: AB | L62: P_G6_DAFFFODILS | M62: AB | N62: AB | O62: AB | P62: AB | Q62: AB | R62: AB | S62: AB | T62: AB | U62: AB | V62: AB | W62: AB | X62: AB | Y62: AB | Z62: AB | AA62: AB | AB62: AB | AC62: AB | AD62: AB | AE62: AB | AF62: AB | AG62: AB | AH62: AB | AI62: AB
A63: 22NGS0048 | B63: Dhruti P | F63: AB | G63: AB | H63: AB | I63: AB | J63: AB | K63: AB | L63: P_G6_DAFFFODILS | M63: AB | N63: AB | O63: AB | P63: AB | Q63: AB | R63: AB | S63: AB | T63: AB | U63: AB | V63: AB | W63: AB | X63: AB | Y63: AB | Z63: AB | AA63: AB | AB63: AB | AC63: AB | AD63: AB | AE63: AB | AF63: AB | AG63: AB | AH63: AB | AI63: AB
A64: 24NGS0303 | B64: KADIRI DEEKSHITH REDDY | F64: AB | G64: AB | H64: AB | I64: AB | J64: AB | K64: AB | L64: P_G6_DAFFFODILS | M64: AB | N64: AB | O64: AB | P64: AB | Q64: AB | R64: AB | S64: AB | T64: AB | U64: AB | V64: AB | W64: AB | X64: AB | Y64: AB | Z64: AB | AA64: AB | AB64: AB | AC64: AB | AD64: AB | AE64: AB | AF64: AB | AG64: AB | AH64: AB | AI64: AB
A65: 24NGS0089 | B65: MAILAPALLI AASHRITHA SIRI | F65: AB | G65: AB | H65: AB | I65: AB | J65: AB | K65: AB | L65: P_G6_DAFFFODILS | M65: AB | N65: AB | O65: AB | P65: AB | Q65: AB | R65: AB | S65: AB | T65: AB | U65: AB | V65: AB | W65: AB | X65: AB | Y65: AB | Z65: AB | AA65: AB | AB65: AB | AC65: AB | AD65: AB | AE65: AB | AF65: AB | AG65: AB | AH65: AB | AI65: AB
A66: 25NGS0207 | B66: ORUGANTI DEEPAK | F66: AB | G66: AB | H66: AB | I66: AB | J66: AB | K66: AB | L66: P_G6_DAFFFODILS | M66: AB | N66: AB | O66: AB | P66: AB | Q66: AB | R66: AB | S66: AB | T66: AB | U66: AB | V66: AB | W66: AB | X66: AB | Y66: AB | Z66: AB | AA66: AB | AB66: AB | AC66: AB | AD66: AB | AE66: AB | AF66: AB | AG66: AB | AH66: AB | AI66: AB
A67: 22NGS0176 | B67: ROHITH KUMAR PADARTHI | F67: AB | G67: AB | H67: AB | I67: AB | J67: AB | K67: AB | L67: P_G6_DAFFFODILS | M67: AB | N67: AB | O67: AB | P67: AB | Q67: AB | R67: AB | S67: AB | T67: AB | U67: AB | V67: AB | W67: AB | X67: AB | Y67: AB | Z67: AB | AA67: AB | AB67: AB | AC67: AB | AD67: AB | AE67: AB | AF67: AB | AG67: AB | AH67: AB | AI67: AB
... A90: 23NGS0154 | B90: T. SRI ROOPA | F90: AB | G90: AB | H90: AB | I90: AB | J90: AB | K90: AB | L90: P_G6_TULIPS | M90: AB | N90: AB | O90: AB | P90: AB | Q90: AB | R90: AB | S90: AB | T90: AB | U90: AB | V90: AB | W90: AB | X90: AB | Y90: AB | Z90: AB | AA90: AB | AB90: AB | AC90: AB | AD90: AB | AE90: AB | AF90: AB | AG90: AB | AH90: AB | AI90: AB

Sheet Sheet1
A1: Select Batch | B1: N_G8_TULIPS
A3: NEO GEETANJALI SCHOOLS
A4: IIT FOUNDATION EXAM-01
A5: Class | B5: =B1 -> N_G8_TULIPS | K5: 45829
A6: BRANCH | B6: =IF(LEFT(B5,1)="P","PRAGATHINAGAR","NIZAMPET") -> NIZAMPET
A7: Average % | B7: =CONCATENATE(LEFT(AVERAGE((J1:J102)),5),"%") -> #DIV/0!
A8: Average Marks | B8: =LEFT(AVERAGE((I11:I1000)),5) -> #DIV/0! | C8: Average Marks: | K8: =LEFT(AVERAGE((K11:K1000)),5) -> #DIV/0! | L8: =LEFT(AVERAGE((L11:L1000)),5) -> #DIV/0! | M8: =LEFT(AVERAGE((M11:M1000)),5) -> #DIV/0! | N8: =LEFT(AVERAGE((N11:N1000)),5) -> #DIV/0! | O8: =LEFT(AVERAGE((O11:O1000)),5) -> #DIV/0! | P8: =LEFT(AVERAGE((P11:P1000)),5) -> #DIV/0! | Q8: =LEFT(AVERAGE((Q11:Q1000)),5) -> #DIV/0!
A9: Username | B9: First Name | C9: Class Rank | E9: OVERALL | K9: Mathematics | N9: Physics | Q9: Chemistry
D10: NGS Rank | E10: CORRECT | F10: INCORRECT | G10: UN-ANSWERED | H10: Time Taken | I10: Score | J10: % | K10: MATHS | L10: No. Of incorrect Answers in Mathematics | M10: No. Of correct Answers in Mathematics | N10: PHY | O10: No. Of incorrect Answers in Physics | P10: No. Of correct Answers in Physics | Q10: CHEM | R10: No. Of incorrect Answers in Chemistry | S10: No. Of correct Answers in Chemistry
A11: {=_xlfn._xlws.FILTER(Score_Sheet!A:B,Score_Sheet!L:L=Sheet1!B1,"NA")} -> NA | C11: =IF(I11="A","A",IF(ISBLANK($A11),"",_xlfn.IFNA(RANK(I11,I:I,0),""))) | E11: {=IF(ISBLANK($A11),"",_xlfn._xlws.FILTER(Score_Sheet!$F:$K,(Score_Sheet!$L:$L=Sheet1!$B$1)*(Score_Sheet!$A:$A=Sheet1!$A11),"NA"))} -> NA | K11: {=IF(ISBLANK($A11),"",_xlfn._xlws.FILTER(Score_Sheet!$AA:$AI,(Score_Sheet!$L:$L=Sheet1!$B$1)*(Score_Sheet!$A:$A=Sheet1!$A11),"NA"))} -> NA
C12: =IF(I12="A","A",IF(ISBLANK($A12),"",_xlfn.IFNA(RANK(I12,I:I,0),""))) | E12: {=IF(ISBLANK($A12),"",_xlfn._xlws.FILTER(Score_Sheet!$F:$K,(Score_Sheet!$L:$L=Sheet1!$B$1)*(Score_Sheet!$A:$A=Sheet1!$A12),"NA"))} | K12: {=IF(ISBLANK($A12),"",_xlfn._xlws.FILTER(Score_Sheet!$AA:$AI,(Score_Sheet!$L:$L=Sheet1!$B$1)*(Score_Sheet!$A:$A=Sheet1!$A12),"NA"))}
C13: =IF(I13="A","A",IF(ISBLANK($A13),"",_xlfn.IFNA(RANK(I13,I:I,0),""))) | E13: {=IF(ISBLANK($A13),"",_xlfn._xlws.FILTER(Score_Sheet!$F:$K,(Score_Sheet!$L:$L=Sheet1!$B$1)*(Score_Sheet!$A:$A=Sheet1!$A13),"NA"))} | K13: {=IF(ISBLANK($A13),"",_xlfn._xlws.FILTER(Score_Sheet!$AA:$AI,(Score_Sheet!$L:$L=Sheet1!$B$1)*(Score_Sheet!$A:$A=Sheet1!$A13),"NA"))}
C14: =IF(I14="A","A",IF(ISBLANK($A14),"",_xlfn.IFNA(RANK(I14,I:I,0),""))) | E14: {=IF(ISBLANK($A14),"",_xlfn._xlws.FILTER(Score_Sheet!$F:$K,(Score_Sheet!$L:$L=Sheet1!$B$1)*(Score_Sheet!$A:$A=Sheet1!$A14),"NA"))} | K14: {=IF(ISBLANK($A14),"",_xlfn._xlws.FILTER(Score_Sheet!$AA:$AI,(Score_Sheet!$L:$L=Sheet1!$B$1)*(Score_Sheet!$A:$A=Sheet1!$A14),"NA"))}
C15: =IF(I15="A","A",IF(ISBLANK($A15),"",_xlfn.IFNA(RANK(I15,I:I,0),""))) | E15: {=IF(ISBLANK($A15),"",_xlfn._xlws.FILTER(Score_Sheet!$F:$K,(Score_Sheet!$L:$L=Sheet1!$B$1)*(Score_Sheet!$A:$A=Sheet1!$A15),"NA"))} | K15: {=IF(ISBLANK($A15),"",_xlfn._xlws.FILTER(Score_Sheet!$AA:$AI,(Score_Sheet!$L:$L=Sheet1!$B$1)*(Score_Sheet!$A:$A=Sheet1!$A15),"NA"))}
C16: =IF(I16="A","A",IF(ISBLANK($A16),"",_xlfn.IFNA(RANK(I16,I:I,0),""))) | E16: {=IF(ISBLANK($A16),"",_xlfn._xlws.FILTER(Score_Sheet!$F:$K,(Score_Sheet!$L:$L=Sheet1!$B$1)*(Score_Sheet!$A:$A=Sheet1!$A16),"NA"))} | K16: {=IF(ISBLANK($A16),"",_xlfn._xlws.FILTER(Score_Sheet!$AA:$AI,(Score_Sheet!$L:$L=Sheet1!$B$1)*(Score_Sheet!$A:$A=Sheet1!$A16),"NA"))}
C17: =IF(I17="A","A",IF(ISBLANK($A17),"",_xlfn.IFNA(RANK(I17,I:I,0),""))) | E17: {=IF(ISBLANK($A17),"",_xlfn._xlws.FILTER(Score_Sheet!$F:$K,(Score_Sheet!$L:$L=Sheet1!$B$1)*(Score_Sheet!$A:$A=Sheet1!$A17),"NA"))} | K17: {=IF(ISBLANK($A17),"",_xlfn._xlws.FILTER(Score_Sheet!$AA:$AI,(Score_Sheet!$L:$L=Sheet1!$B$1)*(Score_Sheet!$A:$A=Sheet1!$A17),"NA"))}
C18: =IF(I18="A","A",IF(ISBLANK($A18),"",_xlfn.IFNA(RANK(I18,I:I,0),""))) | E18: {=IF(ISBLANK($A18),"",_xlfn._xlws.FILTER(Score_Sheet!$F:$K,(Score_Sheet!$L:$L=Sheet1!$B$1)*(Score_Sheet!$A:$A=Sheet1!$A18),"NA"))} | K18: {=IF(ISBLANK($A18),"",_xlfn._xlws.FILTER(Score_Sheet!$AA:$AI,(Score_Sheet!$L:$L=Sheet1!$B$1)*(Score_Sheet!$A:$A=Sheet1!$A18),"NA"))}
C19: =IF(I19="A","A",IF(ISBLANK($A19),"",_xlfn.IFNA(RANK(I19,I:I,0),""))) | E19: {=IF(ISBLANK($A19),"",_xlfn._xlws.FILTER(Score_Sheet!$F:$K,(Score_Sheet!$L:$L=Sheet1!$B$1)*(Score_Sheet!$A:$A=Sheet1!$A19),"NA"))} | K19: {=IF(ISBLANK($A19),"",_xlfn._xlws.FILTER(Score_Sheet!$AA:$AI,(Score_Sheet!$L:$L=Sheet1!$B$1)*(Score_Sheet!$A:$A=Sheet1!$A19),"NA"))}
C20: =IF(I20="A","A",IF(ISBLANK($A20),"",_xlfn.IFNA(RANK(I20,I:I,0),""))) | E20: {=IF(ISBLANK($A20),"",_xlfn._xlws.FILTER(Score_Sheet!$F:$K,(Score_Sheet!$L:$L=Sheet1!$B$1)*(Score_Sheet!$A:$A=Sheet1!$A20),"NA"))} | K20: {=IF(ISBLANK($A20),"",_xlfn._xlws.FILTER(Score_Sheet!$AA:$AI,(Score_Sheet!$L:$L=Sheet1!$B$1)*(Score_Sheet!$A:$A=Sheet1!$A20),"NA"))}
C21: =IF(I21="A","A",IF(ISBLANK($A21),"",_xlfn.IFNA(RANK(I21,I:I,0),""))) | E21: {=IF(ISBLANK($A21),"",_xlfn._xlws.FILTER(Score_Sheet!$F:$K,(Score_Sheet!$L:$L=Sheet1!$B$1)*(Score_Sheet!$A:$A=Sheet1!$A21),"NA"))} | K21: {=IF(ISBLANK($A21),"",_xlfn._xlws.FILTER(Score_Sheet!$AA:$AI,(Score_Sheet!$L:$L=Sheet1!$B$1)*(Score_Sheet!$A:$A=Sheet1!$A21),"NA"))}
C22: =IF(I22="A","A",IF(ISBLANK($A22),"",_xlfn.IFNA(RANK(I22,I:I,0),""))) | E22: {=IF(ISBLANK($A22),"",_xlfn._xlws.FILTER(Score_Sheet!$F:$K,(Score_Sheet!$L:$L=Sheet1!$B$1)*(Score_Sheet!$A:$A=Sheet1!$A22),"NA"))} | K22: {=IF(ISBLANK($A22),"",_xlfn._xlws.FILTER(Score_Sheet!$AA:$AI,(Score_Sheet!$L:$L=Sheet1!$B$1)*(Score_Sheet!$A:$A=Sheet1!$A22),"NA"))}
C23: =IF(I23="A","A",IF(ISBLANK($A23),"",_xlfn.IFNA(RANK(I23,I:I,0),""))) | E23: {=IF(ISBLANK($A23),"",_xlfn._xlws.FILTER(Score_Sheet!$F:$K,(Score_Sheet!$L:$L=Sheet1!$B$1)*(Score_Sheet!$A:$A=Sheet1!$A23),"NA"))} | K23: {=IF(ISBLANK($A23),"",_xlfn._xlws.FILTER(Score_Sheet!$AA:$AI,(Score_Sheet!$L:$L=Sheet1!$B$1)*(Score_Sheet!$A:$A=Sheet1!$A23),"NA"))}
... C47: =IF(I47="A","A",IF(ISBLANK($A47),"",_xlfn.IFNA(RANK(I47,I:I,0),""))) | E47: {=IF(ISBLANK($A47),"",_xlfn._xlws.FILTER(Score_Sheet!$F:$K,(Score_Sheet!$L:$L=Sheet1!$B$1)*(Score_Sheet!$A:$A=Sheet1!$A47),"NA"))} | K47: {=IF(ISBLANK($A47),"",_xlfn._xlws.FILTER(Score_Sheet!$AA:$AI,(Score_Sheet!$L:$L=Sheet1!$B$1)*(Score_Sheet!$A:$A=Sheet1!$A47),"NA"))}
E48: {=IF(ISBLANK($A48),"",_xlfn._xlws.FILTER(Score_Sheet!$F:$K,(Score_Sheet!$L:$L=Sheet1!$B$1)*(Score_Sheet!$A:$A=Sheet1!$A48),"NA"))} | K48: {=IF(ISBLANK($A48),"",_xlfn._xlws.FILTER(Score_Sheet!$AA:$AI,(Score_Sheet!$L:$L=Sheet1!$B$1)*(Score_Sheet!$A:$A=Sheet1!$A48),"NA"))}
E49: {=IF(ISBLANK($A49),"",_xlfn._xlws.FILTER(Score_Sheet!$F:$K,(Score_Sheet!$L:$L=Sheet1!$B$1)*(Score_Sheet!$A:$A=Sheet1!$A49),"NA"))} | K49: {=IF(ISBLANK($A49),"",_xlfn._xlws.FILTER(Score_Sheet!$AA:$AI,(Score_Sheet!$L:$L=Sheet1!$B$1)*(Score_Sheet!$A:$A=Sheet1!$A49),"NA"))}
E50: {=IF(ISBLANK($A50),"",_xlfn._xlws.FILTER(Score_Sheet!$F:$K,(Score_Sheet!$L:$L=Sheet1!$B$1)*(Score_Sheet!$A:$A=Sheet1!$A50),"NA"))} | K50: {=IF(ISBLANK($A50),"",_xlfn._xlws.FILTER(Score_Sheet!$AA:$AI,(Score_Sheet!$L:$L=Sheet1!$B$1)*(Score_Sheet!$A:$A=Sheet1!$A50),"NA"))}
E51: {=IF(ISBLANK($A51),"",_xlfn._xlws.FILTER(Score_Sheet!$F:$K,(Score_Sheet!$L:$L=Sheet1!$B$1)*(Score_Sheet!$A:$A=Sheet1!$A51),"NA"))} | K51: {=IF(ISBLANK($A51),"",_xlfn._xlws.FILTER(Score_Sheet!$AA:$AI,(Score_Sheet!$L:$L=Sheet1!$B$1)*(Score_Sheet!$A:$A=Sheet1!$A51),"NA"))}
E52: {=IF(ISBLANK($A52),"",_xlfn._xlws.FILTER(Score_Sheet!$F:$K,(Score_Sheet!$L:$L=Sheet1!$B$1)*(Score_Sheet!$A:$A=Sheet1!$A52),"NA"))} | K52: {=IF(ISBLANK($A52),"",_xlfn._xlws.FILTER(Score_Sheet!$AA:$AI,(Score_Sheet!$L:$L=Sheet1!$B$1)*(Score_Sheet!$A:$A=Sheet1!$A52),"NA"))}
E53: {=IF(ISBLANK($A53),"",_xlfn._xlws.FILTER(Score_Sheet!$F:$K,(Score_Sheet!$L:$L=Sheet1!$B$1)*(Score_Sheet!$A:$A=Sheet1!$A53),"NA"))} | K53: {=IF(ISBLANK($A53),"",_xlfn._xlws.FILTER(Score_Sheet!$AA:$AI,(Score_Sheet!$L:$L=Sheet1!$B$1)*(Score_Sheet!$A:$A=Sheet1!$A53),"NA"))}
E54: {=IF(ISBLANK($A54),"",_xlfn._xlws.FILTER(Score_Sheet!$F:$K,(Score_Sheet!$L:$L=Sheet1!$B$1)*(Score_Sheet!$A:$A=Sheet1!$A54),"NA"))} | K54: {=IF(ISBLANK($A54),"",_xlfn._xlws.FILTER(Score_Sheet!$AA:$AI,(Score_Sheet!$L:$L=Sheet1!$B$1)*(Score_Sheet!$A:$A=Sheet1!$A54),"NA"))}
E55: {=IF(ISBLANK($A55),"",_xlfn._xlws.FILTER(Score_Sheet!$F:$K,(Score_Sheet!$L:$L=Sheet1!$B$1)*(Score_Sheet!$A:$A=Sheet1!$A55),"NA"))} | K55: {=IF(ISBLANK($A55),"",_xlfn._xlws.FILTER(Score_Sheet!$AA:$AI,(Score_Sheet!$L:$L=Sheet1!$B$1)*(Score_Sheet!$A:$A=Sheet1!$A55),"NA"))}
E56: {=IF(ISBLANK($A56),"",_xlfn._xlws.FILTER(Score_Sheet!$F:$K,(Score_Sheet!$L:$L=Sheet1!$B$1)*(Score_Sheet!$A:$A=Sheet1!$A56),"NA"))} | K56: {=IF(ISBLANK($A56),"",_xlfn._xlws.FILTER(Score_Sheet!$AA:$AI,(Score_Sheet!$L:$L=Sheet1!$B$1)*(Score_Sheet!$A:$A=Sheet1!$A56),"NA"))}
E57: {=IF(ISBLANK($A57),"",_xlfn._xlws.FILTER(Score_Sheet!$F:$K,(Score_Sheet!$L:$L=Sheet1!$B$1)*(Score_Sheet!$A:$A=Sheet1!$A57),"NA"))} | K57: {=IF(ISBLANK($A57),"",_xlfn._xlws.FILTER(Score_Sheet!$AA:$AI,(Score_Sheet!$L:$L=Sheet1!$B$1)*(Score_Sheet!$A:$A=Sheet1!$A57),"NA"))}
E58: {=IF(ISBLANK($A58),"",_xlfn._xlws.FILTER(Score_Sheet!$F:$K,(Score_Sheet!$L:$L=Sheet1!$B$1)*(Score_Sheet!$A:$A=Sheet1!$A58),"NA"))} | K58: {=IF(ISBLANK($A58),"",_xlfn._xlws.FILTER(Score_Sheet!$AA:$AI,(Score_Sheet!$L:$L=Sheet1!$B$1)*(Score_Sheet!$A:$A=Sheet1!$A58),"NA"))}
E59: {=IF(ISBLANK($A59),"",_xlfn._xlws.FILTER(Score_Sheet!$F:$K,(Score_Sheet!$L:$L=Sheet1!$B$1)*(Score_Sheet!$A:$A=Sheet1!$A59),"NA"))} | K59: {=IF(ISBLANK($A59),"",_xlfn._xlws.FILTER(Score_Sheet!$AA:$AI,(Score_Sheet!$L:$L=Sheet1!$B$1)*(Score_Sheet!$A:$A=Sheet1!$A59),"NA"))}
... E233: {=IF(ISBLANK($A233),"",_xlfn._xlws.FILTER(Score_Sheet!$F:$K,(Score_Sheet!$L:$L=Sheet1!$B$1)*(Score_Sheet!$A:$A=Sheet1!$A233),"NA"))} | K233: {=IF(ISBLANK($A233),"",_xlfn._xlws.FILTER(Score_Sheet!$AA:$AI,(Score_Sheet!$L:$L=Sheet1!$B$1)*(Score_Sheet!$A:$A=Sheet1!$A233),"NA"))}

Sheet Class_Wise
A1: Select Batch | B1: N_G6_TULIPS
A3: NEO GEETANJALI SCHOOLS
A4: IIT FOUNDATION - 12
A5: Class | B5: =B1 -> N_G6_TULIPS | O5: 46095
A6: BRANCH | B6: =IF(LEFT(B5,1)="P","PRAGATHINAGAR","NIZAMPET") -> NIZAMPET
A7: Average % | B7: =CONCATENATE(LEFT(AVERAGE((R1:R102)),5),"%") -> 70.00%
A8: Average Marks | B8: =LEFT(AVERAGE((Q11:Q1000)),5) -> 159
A9: Username | B9: Name | C9: RANK | D9: PHY | E9: No. Of incorrect Answers in Mathematics | F9: No. Of correct Answers in Mathematics | G9: CHEM | H9: No. Of incorrect Answers in Physics | I9: No. Of correct Answers in Physics | J9: MATHS | K9: No. Of incorrect Answers in Chemistry | L9: No. Of correct Answers in Chemistry | M9: CORRECT | N9: INCORRECT | O9: UN-ANSWERED | P9: Time Taken | Q9: Score | R9: %
A10: Maximum Marks | D10: 80 | G10: 80 | J10: 80 | Q10: 240 | R10: 100
A11: {=_xlfn._xlws.FILTER(Score_Sheet!A:B,Score_Sheet!L:L=Class_Wise!B1,"NA")} -> 25NGSN6004 | B11: CHETNA SOMBHOTLA | C11: =IF(Q11="AB","AB",IF(ISBLANK($A11),"",_xlfn.IFNA(_xlfn.RANK.EQ(R11,$R$11:$R$100,0),""))) -> 1 | D11: {=IF(ISBLANK($A11),"",_xlfn._xlws.FILTER(Score_Sheet!$AA:$AI,(Score_Sheet!$L:$L=Class_Wise!$B$1)*(Score_Sheet!$A:$A=Class_Wise!$A11),"NA"))} -> 64 | E11: 4 | F11: 16 | G11: 60 | H11: 5 | I11: 15 | J11: 68 | K11: 3 | L11: 17 | M11: {=IF(ISBLANK($A11),"",_xlfn._xlws.FILTER(Score_Sheet!$F:$K,(Score_Sheet!$L:$L=Class_Wise!$B$1)*(Score_Sheet!$A:$A=Class_Wise!$A11),"NA"))} -> 48 | N11: 12 | O11: 0 | P11: 0.038587963 | Q11: 192 | R11: 80
A12: 25NGSN610 | B12: REMALLI LAASYA SRI | C12: =IF(Q12="AB","AB",IF(ISBLANK($A12),"",_xlfn.IFNA(_xlfn.RANK.EQ(R12,$R$11:$R$100,0),""))) -> 2 | D12: {=IF(ISBLANK($A12),"",_xlfn._xlws.FILTER(Score_Sheet!$AA:$AI,(Score_Sheet!$L:$L=Class_Wise!$B$1)*(Score_Sheet!$A:$A=Class_Wise!$A12),"NA"))} -> 72 | E12: 2 | F12: 18 | G12: 56 | H12: 6 | I12: 14 | J12: 60 | K12: 5 | L12: 15 | M12: {=IF(ISBLANK($A12),"",_xlfn._xlws.FILTER(Score_Sheet!$F:$K,(Score_Sheet!$L:$L=Class_Wise!$B$1)*(Score_Sheet!$A:$A=Class_Wise!$A12),"NA"))} -> 47 | N12: 13 | O12: 0 | P12: 0.046724537 | Q12: 188 | R12: 78.33
A13: 25NGSN613 | B13: Ch.V.S Hanvitha | C13: =IF(Q13="AB","AB",IF(ISBLANK($A13),"",_xlfn.IFNA(_xlfn.RANK.EQ(R13,$R$11:$R$100,0),""))) -> 3 | D13: {=IF(ISBLANK($A13),"",_xlfn._xlws.FILTER(Score_Sheet!$AA:$AI,(Score_Sheet!$L:$L=Class_Wise!$B$1)*(Score_Sheet!$A:$A=Class_Wise!$A13),"NA"))} -> 76 | E13: 1 | F13: 19 | G13: 56 | H13: 6 | I13: 14 | J13: 40 | K13: 10 | L13: 10 | M13: {=IF(ISBLANK($A13),"",_xlfn._xlws.FILTER(Score_Sheet!$F:$K,(Score_Sheet!$L:$L=Class_Wise!$B$1)*(Score_Sheet!$A:$A=Class_Wise!$A13),"NA"))} -> 43 | N13: 17 | O13: 0 | P13: 0.041863426 | Q13: 172 | R13: 71.67
A14: 25NGSN6013 | B14: STEENA VANESSA PARISAPOGU | C14: =IF(Q14="AB","AB",IF(ISBLANK($A14),"",_xlfn.IFNA(_xlfn.RANK.EQ(R14,$R$11:$R$100,0),""))) -> 3 | D14: {=IF(ISBLANK($A14),"",_xlfn._xlws.FILTER(Score_Sheet!$AA:$AI,(Score_Sheet!$L:$L=Class_Wise!$B$1)*(Score_Sheet!$A:$A=Class_Wise!$A14),"NA"))} -> 64 | E14: 4 | F14: 16 | G14: 56 | H14: 6 | I14: 14 | J14: 52 | K14: 7 | L14: 13 | M14: {=IF(ISBLANK($A14),"",_xlfn._xlws.FILTER(Score_Sheet!$F:$K,(Score_Sheet!$L:$L=Class_Wise!$B$1)*(Score_Sheet!$A:$A=Class_Wise!$A14),"NA"))} -> 43 | N14: 17 | O14: 0 | P14: 0.053587963 | Q14: 172 | R14: 71.67
A15: 25NGSN618 | B15: G. Sai Vineeth | C15: =IF(Q15="AB","AB",IF(ISBLANK($A15),"",_xlfn.IFNA(_xlfn.RANK.EQ(R15,$R$11:$R$100,0),""))) -> 5 | D15: {=IF(ISBLANK($A15),"",_xlfn._xlws.FILTER(Score_Sheet!$AA:$AI,(Score_Sheet!$L:$L=Class_Wise!$B$1)*(Score_Sheet!$A:$A=Class_Wise!$A15),"NA"))} -> 48 | E15: 8 | F15: 12 | G15: 60 | H15: 5 | I15: 15 | J15: 60 | K15: 5 | L15: 15 | M15: {=IF(ISBLANK($A15),"",_xlfn._xlws.FILTER(Score_Sheet!$F:$K,(Score_Sheet!$L:$L=Class_Wise!$B$1)*(Score_Sheet!$A:$A=Class_Wise!$A15),"NA"))} -> 42 | N15: 18 | O15: 0 | P15: 0.041736111 | Q15: 168 | R15: 70
A16: 25NGSN6009 | B16: PRIYANKA SANI | C16: =IF(Q16="AB","AB",IF(ISBLANK($A16),"",_xlfn.IFNA(_xlfn.RANK.EQ(R16,$R$11:$R$100,0),""))) -> 6 | D16: {=IF(ISBLANK($A16),"",_xlfn._xlws.FILTER(Score_Sheet!$AA:$AI,(Score_Sheet!$L:$L=Class_Wise!$B$1)*(Score_Sheet!$A:$A=Class_Wise!$A16),"NA"))} -> 60 | E16: 5 | F16: 15 | G16: 64 | H16: 4 | I16: 16 | J16: 32 | K16: 12 | L16: 8 | M16: {=IF(ISBLANK($A16),"",_xlfn._xlws.FILTER(Score_Sheet!$F:$K,(Score_Sheet!$L:$L=Class_Wise!$B$1)*(Score_Sheet!$A:$A=Class_Wise!$A16),"NA"))} -> 39 | N16: 21 | O16: 0 | P16: 0.037881944 | Q16: 156 | R16: 65
A17: 25NGSN6005 | B17: KARAPALA KARTHIKA | C17: =IF(Q17="AB","AB",IF(ISBLANK($A17),"",_xlfn.IFNA(_xlfn.RANK.EQ(R17,$R$11:$R$100,0),""))) -> 7 | D17: {=IF(ISBLANK($A17),"",_xlfn._xlws.FILTER(Score_Sheet!$AA:$AI,(Score_Sheet!$L:$L=Class_Wise!$B$1)*(Score_Sheet!$A:$A=Class_Wise!$A17),"NA"))} -> 52 | E17: 7 | F17: 13 | G17: 44 | H17: 9 | I17: 11 | J17: 40 | K17: 10 | L17: 10 | M17: {=IF(ISBLANK($A17),"",_xlfn._xlws.FILTER(Score_Sheet!$F:$K,(Score_Sheet!$L:$L=Class_Wise!$B$1)*(Score_Sheet!$A:$A=Class_Wise!$A17),"NA"))} -> 34 | N17: 26 | O17: 0 | P17: 0.055208333 | Q17: 136 | R17: 56.67
A18: 25NGSN607 | B18: VENKATA KALYANI DUDDU | C18: =IF(Q18="AB","AB",IF(ISBLANK($A18),"",_xlfn.IFNA(_xlfn.RANK.EQ(R18,$R$11:$R$100,0),""))) -> 8 | D18: {=IF(ISBLANK($A18),"",_xlfn._xlws.FILTER(Score_Sheet!$AA:$AI,(Score_Sheet!$L:$L=Class_Wise!$B$1)*(Score_Sheet!$A:$A=Class_Wise!$A18),"NA"))} -> 48 | E18: 8 | F18: 12 | G18: 16 | H18: 16 | I18: 4 | J18: 24 | K18: 14 | L18: 6 | M18: {=IF(ISBLANK($A18),"",_xlfn._xlws.FILTER(Score_Sheet!$F:$K,(Score_Sheet!$L:$L=Class_Wise!$B$1)*(Score_Sheet!$A:$A=Class_Wise!$A18),"NA"))} -> 22 | N18: 38 | O18: 0 | P18: 0.026412037 | Q18: 88 | R18: 36.67
A19: 25NGSN6001 | B19: AAHIL MOHAMMED | C19: =IF(Q19="AB","AB",IF(ISBLANK($A19),"",_xlfn.IFNA(_xlfn.RANK.EQ(R19,$R$11:$R$100,0),""))) -> AB | D19: {=IF(ISBLANK($A19),"",_xlfn._xlws.FILTER(Score_Sheet!$AA:$AI,(Score_Sheet!$L:$L=Class_Wise!$B$1)*(Score_Sheet!$A:$A=Class_Wise!$A19),"NA"))} -> AB | E19: AB | F19: AB | G19: AB | H19: AB | I19: AB | J19: AB | K19: AB | L19: AB | M19: {=IF(ISBLANK($A19),"",_xlfn._xlws.FILTER(Score_Sheet!$F:$K,(Score_Sheet!$L:$L=Class_Wise!$B$1)*(Score_Sheet!$A:$A=Class_Wise!$A19),"NA"))} -> AB | N19: AB | O19: AB | P19: AB | Q19: AB | R19: AB
A20: 25NGSN6003 | B20: BHARGAVI DUBBA | C20: =IF(Q20="AB","AB",IF(ISBLANK($A20),"",_xlfn.IFNA(_xlfn.RANK.EQ(R20,$R$11:$R$100,0),""))) -> AB | D20: {=IF(ISBLANK($A20),"",_xlfn._xlws.FILTER(Score_Sheet!$AA:$AI,(Score_Sheet!$L:$L=Class_Wise!$B$1)*(Score_Sheet!$A:$A=Class_Wise!$A20),"NA"))} -> AB | E20: AB | F20: AB | G20: AB | H20: AB | I20: AB | J20: AB | K20: AB | L20: AB | M20: {=IF(ISBLANK($A20),"",_xlfn._xlws.FILTER(Score_Sheet!$F:$K,(Score_Sheet!$L:$L=Class_Wise!$B$1)*(Score_Sheet!$A:$A=Class_Wise!$A20),"NA"))} -> AB | N20: AB | O20: AB | P20: AB | Q20: AB | R20: AB
A21: 25NGSN608 | B21: P NIRVIGNA | C21: =IF(Q21="AB","AB",IF(ISBLANK($A21),"",_xlfn.IFNA(_xlfn.RANK.EQ(R21,$R$11:$R$100,0),""))) -> AB | D21: {=IF(ISBLANK($A21),"",_xlfn._xlws.FILTER(Score_Sheet!$AA:$AI,(Score_Sheet!$L:$L=Class_Wise!$B$1)*(Score_Sheet!$A:$A=Class_Wise!$A21),"NA"))} -> AB | E21: AB | F21: AB | G21: AB | H21: AB | I21: AB | J21: AB | K21: AB | L21: AB | M21: {=IF(ISBLANK($A21),"",_xlfn._xlws.FILTER(Score_Sheet!$F:$K,(Score_Sheet!$L:$L=Class_Wise!$B$1)*(Score_Sheet!$A:$A=Class_Wise!$A21),"NA"))} -> AB | N21: AB | O21: AB | P21: AB | Q21: AB | R21: AB
A22: 25NGSN617 | B22: A. Vedick | C22: =IF(Q22="AB","AB",IF(ISBLANK($A22),"",_xlfn.IFNA(_xlfn.RANK.EQ(R22,$R$11:$R$100,0),""))) -> AB | D22: {=IF(ISBLANK($A22),"",_xlfn._xlws.FILTER(Score_Sheet!$AA:$AI,(Score_Sheet!$L:$L=Class_Wise!$B$1)*(Score_Sheet!$A:$A=Class_Wise!$A22),"NA"))} -> AB | E22: AB | F22: AB | G22: AB | H22: AB | I22: AB | J22: AB | K22: AB | L22: AB | M22: {=IF(ISBLANK($A22),"",_xlfn._xlws.FILTER(Score_Sheet!$F:$K,(Score_Sheet!$L:$L=Class_Wise!$B$1)*(Score_Sheet!$A:$A=Class_Wise!$A22),"NA"))} -> AB | N22: AB | O22: AB | P22: AB | Q22: AB | R22: AB
C23: =IF(Q23="AB","AB",IF(ISBLANK($A23),"",_xlfn.IFNA(_xlfn.RANK.EQ(R23,$R$11:$R$100,0),""))) | D23: {=IF(ISBLANK($A23),"",_xlfn._xlws.FILTER(Score_Sheet!$AA:$AI,(Score_Sheet!$L:$L=Class_Wise!$B$1)*(Score_Sheet!$A:$A=Class_Wise!$A23),"NA"))} | M23: {=IF(ISBLANK($A23),"",_xlfn._xlws.FILTER(Score_Sheet!$F:$K,(Score_Sheet!$L:$L=Class_Wise!$B$1)*(Score_Sheet!$A:$A=Class_Wise!$A23),"NA"))}
C24: =IF(Q24="AB","AB",IF(ISBLANK($A24),"",_xlfn.IFNA(_xlfn.RANK.EQ(R24,$R$11:$R$100,0),""))) | D24: {=IF(ISBLANK($A24),"",_xlfn._xlws.FILTER(Score_Sheet!$AA:$AI,(Score_Sheet!$L:$L=Class_Wise!$B$1)*(Score_Sheet!$A:$A=Class_Wise!$A24),"NA"))} | M24: {=IF(ISBLANK($A24),"",_xlfn._xlws.FILTER(Score_Sheet!$F:$K,(Score_Sheet!$L:$L=Class_Wise!$B$1)*(Score_Sheet!$A:$A=Class_Wise!$A24),"NA"))}
C25: =IF(Q25="AB","AB",IF(ISBLANK($A25),"",_xlfn.IFNA(_xlfn.RANK.EQ(R25,$R$11:$R$100,0),""))) | D25: {=IF(ISBLANK($A25),"",_xlfn._xlws.FILTER(Score_Sheet!$AA:$AI,(Score_Sheet!$L:$L=Class_Wise!$B$1)*(Score_Sheet!$A:$A=Class_Wise!$A25),"NA"))} | M25: {=IF(ISBLANK($A25),"",_xlfn._xlws.FILTER(Score_Sheet!$F:$K,(Score_Sheet!$L:$L=Class_Wise!$B$1)*(Score_Sheet!$A:$A=Class_Wise!$A25),"NA"))}
C26: =IF(Q26="AB","AB",IF(ISBLANK($A26),"",_xlfn.IFNA(_xlfn.RANK.EQ(R26,$R$11:$R$100,0),""))) | D26: {=IF(ISBLANK($A26),"",_xlfn._xlws.FILTER(Score_Sheet!$AA:$AI,(Score_Sheet!$L:$L=Class_Wise!$B$1)*(Score_Sheet!$A:$A=Class_Wise!$A26),"NA"))} | M26: {=IF(ISBLANK($A26),"",_xlfn._xlws.FILTER(Score_Sheet!$F:$K,(Score_Sheet!$L:$L=Class_Wise!$B$1)*(Score_Sheet!$A:$A=Class_Wise!$A26),"NA"))}
C27: =IF(Q27="AB","AB",IF(ISBLANK($A27),"",_xlfn.IFNA(_xlfn.RANK.EQ(R27,$R$11:$R$100,0),""))) | D27: {=IF(ISBLANK($A27),"",_xlfn._xlws.FILTER(Score_Sheet!$AA:$AI,(Score_Sheet!$L:$L=Class_Wise!$B$1)*(Score_Sheet!$A:$A=Class_Wise!$A27),"NA"))} | M27: {=IF(ISBLANK($A27),"",_xlfn._xlws.FILTER(Score_Sheet!$F:$K,(Score_Sheet!$L:$L=Class_Wise!$B$1)*(Score_Sheet!$A:$A=Class_Wise!$A27),"NA"))}
C28: =IF(Q28="AB","AB",IF(ISBLANK($A28),"",_xlfn.IFNA(_xlfn.RANK.EQ(R28,$R$11:$R$100,0),""))) | D28: {=IF(ISBLANK($A28),"",_xlfn._xlws.FILTER(Score_Sheet!$AA:$AI,(Score_Sheet!$L:$L=Class_Wise!$B$1)*(Score_Sheet!$A:$A=Class_Wise!$A28),"NA"))} | M28: {=IF(ISBLANK($A28),"",_xlfn._xlws.FILTER(Score_Sheet!$F:$K,(Score_Sheet!$L:$L=Class_Wise!$B$1)*(Score_Sheet!$A:$A=Class_Wise!$A28),"NA"))}
C29: =IF(Q29="AB","AB",IF(ISBLANK($A29),"",_xlfn.IFNA(_xlfn.RANK.EQ(R29,$R$11:$R$100,0),""))) | D29: {=IF(ISBLANK($A29),"",_xlfn._xlws.FILTER(Score_Sheet!$AA:$AI,(Score_Sheet!$L:$L=Class_Wise!$B$1)*(Score_Sheet!$A:$A=Class_Wise!$A29),"NA"))} | M29: {=IF(ISBLANK($A29),"",_xlfn._xlws.FILTER(Score_Sheet!$F:$K,(Score_Sheet!$L:$L=Class_Wise!$B$1)*(Score_Sheet!$A:$A=Class_Wise!$A29),"NA"))}
C30: =IF(Q30="AB","AB",IF(ISBLANK($A30),"",_xlfn.IFNA(_xlfn.RANK.EQ(R30,$R$11:$R$100,0),""))) | D30: {=IF(ISBLANK($A30),"",_xlfn._xlws.FILTER(Score_Sheet!$AA:$AI,(Score_Sheet!$L:$L=Class_Wise!$B$1)*(Score_Sheet!$A:$A=Class_Wise!$A30),"NA"))} | M30: {=IF(ISBLANK($A30),"",_xlfn._xlws.FILTER(Score_Sheet!$F:$K,(Score_Sheet!$L:$L=Class_Wise!$B$1)*(Score_Sheet!$A:$A=Class_Wise!$A30),"NA"))}
C31: =IF(Q31="AB","AB",IF(ISBLANK($A31),"",_xlfn.IFNA(_xlfn.RANK.EQ(R31,$R$11:$R$100,0),""))) | D31: {=IF(ISBLANK($A31),"",_xlfn._xlws.FILTER(Score_Sheet!$AA:$AI,(Score_Sheet!$L:$L=Class_Wise!$B$1)*(Score_Sheet!$A:$A=Class_Wise!$A31),"NA"))} | M31: {=IF(ISBLANK($A31),"",_xlfn._xlws.FILTER(Score_Sheet!$F:$K,(Score_Sheet!$L:$L=Class_Wise!$B$1)*(Score_Sheet!$A:$A=Class_Wise!$A31),"NA"))}
C32: =IF(Q32="AB","AB",IF(ISBLANK($A32),"",_xlfn.IFNA(_xlfn.RANK.EQ(R32,$R$11:$R$100,0),""))) | D32: {=IF(ISBLANK($A32),"",_xlfn._xlws.FILTER(Score_Sheet!$AA:$AI,(Score_Sheet!$L:$L=Class_Wise!$B$1)*(Score_Sheet!$A:$A=Class_Wise!$A32),"NA"))} | M32: {=IF(ISBLANK($A32),"",_xlfn._xlws.FILTER(Score_Sheet!$F:$K,(Score_Sheet!$L:$L=Class_Wise!$B$1)*(Score_Sheet!$A:$A=Class_Wise!$A32),"NA"))}
C33: =IF(Q33="AB","AB",IF(ISBLANK($A33),"",_xlfn.IFNA(_xlfn.RANK.EQ(R33,$R$11:$R$100,0),""))) | D33: {=IF(ISBLANK($A33),"",_xlfn._xlws.FILTER(Score_Sheet!$AA:$AI,(Score_Sheet!$L:$L=Class_Wise!$B$1)*(Score_Sheet!$A:$A=Class_Wise!$A33),"NA"))} | M33: {=IF(ISBLANK($A33),"",_xlfn._xlws.FILTER(Score_Sheet!$F:$K,(Score_Sheet!$L:$L=Class_Wise!$B$1)*(Score_Sheet!$A:$A=Class_Wise!$A33),"NA"))}
C34: =IF(Q34="AB","AB",IF(ISBLANK($A34),"",_xlfn.IFNA(_xlfn.RANK.EQ(R34,$R$11:$R$100,0),""))) | D34: {=IF(ISBLANK($A34),"",_xlfn._xlws.FILTER(Score_Sheet!$AA:$AI,(Score_Sheet!$L:$L=Class_Wise!$B$1)*(Score_Sheet!$A:$A=Class_Wise!$A34),"NA"))} | M34: {=IF(ISBLANK($A34),"",_xlfn._xlws.FILTER(Score_Sheet!$F:$K,(Score_Sheet!$L:$L=Class_Wise!$B$1)*(Score_Sheet!$A:$A=Class_Wise!$A34),"NA"))}
... C58: =IF(Q58="AB","AB",IF(ISBLANK($A58),"",_xlfn.IFNA(_xlfn.RANK.EQ(R58,$R$11:$R$100,0),""))) | D58: {=IF(ISBLANK($A58),"",_xlfn._xlws.FILTER(Score_Sheet!$AA:$AI,(Score_Sheet!$L:$L=Class_Wise!$B$1)*(Score_Sheet!$A:$A=Class_Wise!$A58),"NA"))} | M58: {=IF(ISBLANK($A58),"",_xlfn._xlws.FILTER(Score_Sheet!$F:$K,(Score_Sheet!$L:$L=Class_Wise!$B$1)*(Score_Sheet!$A:$A=Class_Wise!$A58),"NA"))}
D59: {=IF(ISBLANK($A59),"",_xlfn._xlws.FILTER(Score_Sheet!$AA:$AI,(Score_Sheet!$L:$L=Class_Wise!$B$1)*(Score_Sheet!$A:$A=Class_Wise!$A59),"NA"))} | M59: {=IF(ISBLANK($A59),"",_xlfn._xlws.FILTER(Score_Sheet!$F:$K,(Score_Sheet!$L:$L=Class_Wise!$B$1)*(Score_Sheet!$A:$A=Class_Wise!$A59),"NA"))}
D60: {=IF(ISBLANK($A60),"",_xlfn._xlws.FILTER(Score_Sheet!$AA:$AI,(Score_Sheet!$L:$L=Class_Wise!$B$1)*(Score_Sheet!$A:$A=Class_Wise!$A60),"NA"))} | M60: {=IF(ISBLANK($A60),"",_xlfn._xlws.FILTER(Score_Sheet!$F:$K,(Score_Sheet!$L:$L=Class_Wise!$B$1)*(Score_Sheet!$A:$A=Class_Wise!$A60),"NA"))}
D61: {=IF(ISBLANK($A61),"",_xlfn._xlws.FILTER(Score_Sheet!$AA:$AI,(Score_Sheet!$L:$L=Class_Wise!$B$1)*(Score_Sheet!$A:$A=Class_Wise!$A61),"NA"))} | M61: {=IF(ISBLANK($A61),"",_xlfn._xlws.FILTER(Score_Sheet!$F:$K,(Score_Sheet!$L:$L=Class_Wise!$B$1)*(Score_Sheet!$A:$A=Class_Wise!$A61),"NA"))}
D62: {=IF(ISBLANK($A62),"",_xlfn._xlws.FILTER(Score_Sheet!$AA:$AI,(Score_Sheet!$L:$L=Class_Wise!$B$1)*(Score_Sheet!$A:$A=Class_Wise!$A62),"NA"))} | M62: {=IF(ISBLANK($A62),"",_xlfn._xlws.FILTER(Score_Sheet!$F:$K,(Score_Sheet!$L:$L=Class_Wise!$B$1)*(Score_Sheet!$A:$A=Class_Wise!$A62),"NA"))}
D63: {=IF(ISBLANK($A63),"",_xlfn._xlws.FILTER(Score_Sheet!$AA:$AI,(Score_Sheet!$L:$L=Class_Wise!$B$1)*(Score_Sheet!$A:$A=Class_Wise!$A63),"NA"))} | M63: {=IF(ISBLANK($A63),"",_xlfn._xlws.FILTER(Score_Sheet!$F:$K,(Score_Sheet!$L:$L=Class_Wise!$B$1)*(Score_Sheet!$A:$A=Class_Wise!$A63),"NA"))}
D64: {=IF(ISBLANK($A64),"",_xlfn._xlws.FILTER(Score_Sheet!$AA:$AI,(Score_Sheet!$L:$L=Class_Wise!$B$1)*(Score_Sheet!$A:$A=Class_Wise!$A64),"NA"))} | M64: {=IF(ISBLANK($A64),"",_xlfn._xlws.FILTER(Score_Sheet!$F:$K,(Score_Sheet!$L:$L=Class_Wise!$B$1)*(Score_Sheet!$A:$A=Class_Wise!$A64),"NA"))}
...
